`try..catch` 와 에러 핸들링
=========================

- 에러 원인
  - 실수
  - 예상치 못한 사용자 입력
  - 잘못된 서버 응답
  - 기타 등등
- 에러 발생 시
  - 스크립트는 즉시 중단
  - 콘솔 : 에러 출력

- `try…catch` 문법
  - 스크립트 중단 방지
  - 에러 '잡음 <sub>(catch)</sub>'
    - 더 합당한 무언가 실행

### `try…catch` 문법
- 구성
  - `try` 블록
  - `catch` 블록
```javascript
try {

  // 코드…

} catch (err) {

  // 에러 핸들링

}
```
##### `try…catch` 동작 알고리즘
1. `try { … }` 안 코드 실행
2. 에러 無
    - `try` 안 마지막 줄까지 실행
    - `catch` 블록 스킵
3. 에러 有
    - `try` 코드 실행 중단
    - 제어 흐름 → `catch(err)` 블록
    - `err` <sub>(변수)</sub>
      - 에러 객체 포함
      - 무슨 일 일어났는지 설명

![try-catch-flow](../../images/10/01/try-catch-flow.svg)

- 에러 無 예시
```javascript
try {

  alert('try 블록 시작');

  // … 에러 無 …

  alert('try 블록 끝');

// catch 문 무시
} catch(err) {

  alert('에러 無 → catch 무시');

}
```
- 에러 有 예시
```javascript
try {

  alert('try 블록 시작');

  lalala; // 에러 (변수 정의 X)

  alert('try 블록 끝'); // 도달 X

} catch(err) {

  alert('에러 발생');

}
```

<img class="icon" src="../../images/commons/icons/triangle-exclamation-solid.svg" /> **`try…catch` : 오직 런타임 에러에만 동작**

- 실행 가능한 코드에만 동작
- 실행 가능한 <sub>(runnable)</sub> 코드
  - 유효한 JS 코드
- 문법적으로 잘못된 코드
  - `try…catch` 동작 X
  - ex&#41; 중괄호 짝 안 맞음

```javascript
try {
  {{{{{{{{{{{{
    } catch(e) {
      alert("유효하지 않은 코드 → JS 엔진 코드 이해 X");
}
```
- JS 엔진
  - 코드 읽은 후 실행

##### 에러 구분
- 코드 읽는 중 발생
  - parse-time error
  - 엔진 : 코드 이해 X
    - 코드 안에서 복구 X
- 유효한 코드에서 발생
  - runtime error <sub>(런타임 에러)</sub>
  - exception <sub>(예외)</sub>
  - `try…catch` 담당

<img class="icon" src="../../images/commons/icons/triangle-exclamation-solid.svg" /> **`try…catch` : 동기적으로 동작**

- '스케줄 된 <sub>(scheduled)</sub>' 코드
  - ex&#41; `setTimeout`
  - `try…catch` 처리 X
```javascript
try {
  setTimeout(function() {
    noSuchVariable; // 스크립트 여기서 중단
  }, 1000);
} catch (e) {
  alert( "작동 멈춤" );
}
```
- `setTimeout` 전달 익명 함수
  - 엔진 : `try…catch` 떠난 다음 실행
  - 함수 내부에 사용
```javascript
setTimeout(function() {
  try {
    noSuchVariable; // try…catch 에서 에러 핸들링
  } catch {
    alert( "에러를 잡았습니다!" );
  }
}, 1000);
```

### 에러 객체

##### 에러 발생 시
- 에러 상세 내용 객체 생성 후
  - `catch` 블록 인수 전달
```javascript
try {
  // …
} catch(err) { // err : 에러 객체
               // - 아무 이름 가능
  // …
}
```

##### 주요 프로퍼티 <sub>(내장 에러 전체 · 에러 객체)</sub>
- `name`
  - 에러 이름
  - ex&#41; `'ReferenceError'`
    - "미정의 변수 에러"
- `message`
  - 에러 상세 내용 <sub>(문자열)</sub>

##### 이외 프로퍼티 <sub>(표준 X · 대부분의 호스트 환경 지원)</sub>
- `stack` <sub>(가장 널리 사용)</sub>
  - 현재 호출 스택
  - 에러 유발 중첩 호출들 순서 정보 <sub>(문자열)</sub>
    - 디버깅 목적
```javascript
try {
  lalala; // 에러, 변수 미정의
} catch(err) {
  alert(err.name);    // ReferenceError
  alert(err.message); // lalala is not defined
  alert(err.stack);   // ReferenceError: lalala is not defined at … (호출 스택)

  // 에러 전체 표시
  // - 에러 (객체) → "name: message" 형태 문자열 변환
  alert(err); // ReferenceError: lalala is not defined
}
```

### 선택적 `catch` 바인딩
<img class="icon" src="../../images/commons/icons/triangle-exclamation-solid.svg" /> **최근 추가됨**

- 스펙 추가된 지 얼마 안 된 문법
- 구식 브라우저
  - 폴리필 필요

<br />

- 자세한 에러 정보 불필요 시
  - `catch` 인수 생략
```javascript
try {
  // …
} catch { // err (인수) 없이 사용 가능
  // …
}
```

### `try…catch` 사용하기

##### `JSON.parse(str)` <sub>(메서드)</sub>
- JSON 인코딩된 값 읽기
- 네트워크 <sub>(서버 등)</sub> 통해 전달받은 데이터 디코딩

##### 전달받은 데이터에 호출
```javascript
// 서버에서 전달받은 데이터
let json = '{"name":"John", "age": 30}';

// 전달받은 문자열 → JS 객체 변환
let user = JSON.parse(json);

// 문자열 형태 user (객체) → 객체 변환
alert( user.name ); // John
alert( user.age );  // 30
```
- 잘못된 형식의 JSON
  - `JSON.parse` 에러 발생
  - 스크립트 중단
- 전달받은 데이터 문제로 스크립트 중단 시
  - 콘솔 외 원인 파악 불가능
  - `try…catch` 사용해 처리
```javascript
let json = "{ bad json }";

try {

  let user = JSON.parse(json); // 에러 발생
  alert( user.name );          // 코드 동작 X

} catch (e) {

  // 에러 발생
  // - 제어 흐름 → catch (문)
  alert( "데이터에 에러가 있어 재요청을 시도합니다." );
  alert( e.name );
  alert( e.message );
}
```

##### `catch` 블록 안
- 구체적인 동작 실행 가능
  - 새로운 네트워크 요청 보내기
  - 사용자에게 대안 제안하기
  - 로깅 장치에 에러 정보 보내기
  - 기타 등등
- 스크립트 중단보다 훨씬 나은 대응

### 직접 에러 만들어서 던지기

- 문법적으로 정상 · 불완전 데이터
```javascript
let json = '{ "age": 30 }'; // 불완전 데이터
                            // name (프로퍼티) 부재

try {

  let user = JSON.parse(json); // 에러 X
  alert( user.name );          // name (프로퍼티) 부재

} catch (e) {
  alert( "실행되지 않습니다." );
}
```
- `JSON.parse` 정상 실행
  - `name` <sub>(프로퍼티)</sub> 부재
    - 에러 유발 상황
- `throw` <sub>(연산자)</sub>
  - 에러 처리 통합 시 사용

#### `throw` <sub>(연산자)</sub>
- 에러 생성
```javascript
throw <error object>
```

##### 에러 객체
- 이론적으로 어떤 것이든 가능
  - 원시형 자료 등
- `name` · `message` <sub>(프로퍼티)</sub> 권장
  - 내장 에러 호환
- 표준 에러 객체 관련 생성자 지원
  - `Error`
  - `SyntaxError`
  - `ReferenceError`
  - `TypeError`
  - 기타 등
```javascript
let error = new Error(message);
let error = new SyntaxError(message);
let error = new ReferenceError(message);
// …
```

##### 내장 에러 객체
- 내장 생성자로 생성
  - 일반 객체 X
- `name` <sub>(프로퍼티)</sub>
  - 생성자 이름
- `message` <sub>(프로퍼티)</sub>
  - 인수에서 가져옴
```javascript
let error = new Error("이상한 일이 발생했습니다. o_O");

alert(error.name);    // Error
alert(error.message); // 이상한 일이 발생했습니다. o_O
```

##### `JSON.parse` 생성 에러
- `SyntaxError`
  - 잘못된 데이터 받았을 때
```javascript
try {
  JSON.parse("{ 잘못된 형식의 json o_O }");
} catch(e) {
  alert(e.name);    // SyntaxError
  alert(e.message); // Unexpected token b in JSON at position 2
}
```

##### 예외 처리
- `name` 부재 시
  - 에러 발생 간주
- 에러 던지기
  - `throw` <sub>(연산자)</sub> 사용
```javascript
let json = '{ "age": 30 }'; // 불완전 데이터
                            // name (프로퍼티) 부재

try {

  let user = JSON.parse(json); // 에러 X

  if (!user.name) {

    /*
     throw (연산자)
       - message 이용해 SyntaxError 생성
       - JS 자체 에러 생성 방식 동일
     try 실행 즉시 중단
       - 제어 흐름 → catch

     */
    throw new SyntaxError("불완전 데이터 (이름 없음)");
  }

  alert( user.name );

// catch 블록 안
// - 모든 에러 처리
//   - JSON.parse 에러 포함
} catch(e) {
  alert( "JSON Error: " + e.message ); // JSON Error: 불완전 데이터 (이름 없음)
}
```

### 에러 다시 던지기
- 또 다른 예기치 않은 에러
  - 미정의 변수 사용
  - 기타 등등
```javascript
let json = '{ "age": 30 }'; // 불완전 데이터

try {
  user = JSON.parse(json); // let 선언 X

  // …
} catch(err) {

  // JSON Error: ReferenceError: user is not defined
  alert("JSON Error: " + err);
}
```

##### `catch`
- `try` 블록 내 모든 에러 처리
- 예상치 못한 에러 (미정의 변수 등)
  - 잡기는 함
  - 항상 특정 내용 <sub>(`"JSON Error"`)</sub> 표시
    - 에러 종류 관계 X
- 종류 관계없이 동일 방식 에러 처리
  - 디버깅 난이도 ↑

##### 다시 던지기 <sub>(rethrowing)</sub>
- `catch`
  - 알고 있는 에러만 처리
  - 나머지 '다시 던짐'

##### 규칙 순서
1. `catch`
    - 모든 에러 받음
2. `catch(err) { … }` 블록 안
    - `err` <sub>(에러 객체)</sub> 분석
3. 에러 처리 방법 알지 못함
    - `throw err` <sub>(다시 던지기)</sub>

<br />

- 일반적인 에러 타입 체크
  - `instanceof` <sub>(연산자)</sub>
```javascript
try {
  user = { /* … */ };
} catch(err) {
  if (err instanceof ReferenceError) {

  // 미정의 변수 접근
  // - ReferenceError 발생
    alert('ReferenceError');
  }
}
```
- `err.name` <sub>(프로퍼티)</sub>
  - 에러 클래스명
  - 모든 기본형 에러 보유
  - == `err.constructor.name`

##### 에러 다시 던지기
- `catch` 블록
  - `SyntaxError` 만 처리
```javascript
let json = '{ "age": 30 }'; // 불완전 데이터
try {

  let user = JSON.parse(json);

  if (!user.name) {
    throw new SyntaxError("불완전 데이터 (이름 없음)");
  }

  blabla(); // 예상치 못한 에러

  alert( user.name );

} catch(e) {

  if (e instanceof SyntaxError) {
    alert( "JSON Error: " + e.message );

  // 이외 예기치 못한 에러
  } else {
    throw e; // 다시 던지기
  }
}
```
- 다시 던져진 에러 <sub>(`catch` 블록)</sub>
  - `try…catch` 밖으로 던져짐
- 바깥 `try…catch`
  - 존재 시
    - 던져진 에러 잡음
  - 부재 시
    - 스크립트 중단
- `catch` 블록
  - 어떻게 다룰지 아는 에러만 처리
  - 알 수 없는 에러 건너뜀 <sub>(처리 X)</sub>
- 다시 던져진 예상치 못한 에러 처리
```javascript
function readData() {
  let json = '{ "age": 30 }';

  try {
    // ...
    blabla(); // 에러 발생
  } catch (e) {
    // ...
    if (!(e instanceof SyntaxError)) {
      throw e; // (알 수 없는) 에러 다시 던지기
    }
  }
}

try {
  readData();
} catch (e) {

  // 다시 던져진 에러
  // - 밖의 try…catch 잡음
  alert( "External catch got: " + e );
}
```
- `readData` <sub>(함수)</sub>
  - `SyntaxError` 만 처리
- 함수 밖 `try…catch`
  - 예상치 못한 에러 처리

### `try…catch…finally`

##### `finally`
- 에러 부재 시
  - `try` 실행 후 실행
- 에러 발생 시
  - `catch` 실행 후 실행
- `try…catch` 확장
```javascript
try {
   … 코드 실행 …
} catch(e) {
   … 에러 핸들링 …
} finally {
   … 항상 실행 …
}
```
```javascript
try {
  alert( 'try 블록 시작' );
  if (confirm('에러를 만드시겠습니까?')) {
    이상한_코드();
  }
} catch (e) {
  alert( 'catch' );
} finally {
  alert( 'finally' );
}
```
##### 코드 실행 경로
- `"에러를 만드시겠습니까?"`
1. Yes
    - `try` → `catch` → `finally`
2. No
    - `try` → `finally`

##### `finally` <sub>(절)</sub>
- 무언가 실행 후
  - 결과 상관없이 실행

##### ex&#41; `fib(n)` <sub>(피보나치 함수)</sub>
- 연산 시간 측정
  - 함수 실행 전 측정 시작
  - 함수 실행 후 측정 종료
- 함수 실행 도중 에러 발생 경우
  - 정수 아닌 수 · 음수 입력 등
- `finally`
  - 결과 상관없이 연산 시간 측정
```javascript
let num = +prompt("양의 정수를 입력해주세요.", 35)

let diff, result;

function fib(n) {
  if (n < 0 || Math.trunc(n) != n) {
    throw new Error("음수나 정수가 아닌 값은 처리할 수 없습니다.");
  }
  return n <= 1 ? n : fib(n - 1) + fib(n - 2);
}

let start = Date.now();

try {
  result = fib(num);
} catch (e) {
  result = 0;
} finally {
  diff = Date.now() - start;
}

alert(result || "에러 발생");

alert( `연산 시간: ${diff}ms` );
```

##### 프롬프트 대화상자 입력 값
- `35`
  - `try` 다음 `finally` 정상 실행
    - 연산 시간 계산 정상 실행
- `-1`
  - 에러 발생
    - 연산 시간 : `0ms`
- 함수 종료
  - `return` · `throw` <sub>(문)</sub> 도달
  - `finally` <sub>(절)</sub>
    - 두 경우 모두 처리

<img class="icon" src="../../images/commons/icons/circle-exclamation-solid.svg" /> **`try…catch…finally` 안 변수 : 지역 변수**

- 위 예시 `diff` · `result` <sub>(변수)</sub>
  - `try…catch` 이전 선언
- `try` 블록 내 선언 변수
  - 지역 변수 <sub>(블록 안에서만 유효)</sub>

<img class="icon" src="../../images/commons/icons/circle-exclamation-solid.svg" /> **`finally` · `return`**

##### `finally` <sub>(절)</sub> 실행
- `try…catch` 절 빠져나가는 모든 경우
- `return` 사용해 명시적으로 빠져나가는 경우
- `try` 블록 내 `return` 사용 시
  - 바깥 코드로 값 반환 전 실행
```javascript
function func() {
  try {
    return 1;
  } catch (e) {
    /* … */
  } finally {
    alert( 'finally' );
  }
}

alert( func() ); // finally (절) alert 실행 후 실행
```

<img class="icon" src="../../images/commons/icons/circle-exclamation-solid.svg" /> **`try…finally 구문`**

- `catch` <sub>(절)</sub> 생략
- 상황 따라 유용
- `try…finally` 내 에러 처리 X
  - 프로세스 마무리 확인 등
```javascript
function func() {
  // 끝맺음 있어야 하는 어떤 프로세스
  // - 무언가 측정 등
  try {
    // …
  } finally {
    // 스크립트 중단되더라도 완료
  }
}
```
- `try` 내 발생 에러
  - 항상 밖으로 떨어져 나옴
- `finally`
  - 실행 흐름이 함수 떠나기 전 실행

### 전역 `catch`

<img class="icon" src="../../images/commons/icons/triangle-exclamation-solid.svg" /> **호스트 환경 확인**

- 코어 JS X

<br />

##### 상황 가정
- `try…catch` 바깥
  - 치명적인 에러 발생해 스크립트 중단
- 대처 방법
  - 어딘가 에러 내역 기록
  - 사용자에게 에러 발생 알림
  - 기타 등등
- JS 명세서
  - 치명적인 에러 대응 방법 X
- `try…catch` 미처리 에러 잡기
  - 아주 중요
- 대부분의 JS 호스트 환경
  - 자체 에러 처리 기능 제공

##### Node.js
- `process.on("uncaughtException")`

##### 브라우저
- `window.onerror` <sub>(함수 할당)</sub>
  - 예상치 못한 에러 발생 시 함수 실행
```javascript
window.onerror = function(message, url, line, col, error) {
  // …
};
```
- `message`
  - 에러 메시지
- `url`
  - 에러 발생 스크립트 URL
- `line` · `col`
  - 에러 발생 위치 줄 · 열
- `error`
  - 에러 객체
```html
<script>
  window.onerror = function(message, url, line, col, error) {
    alert(`${message}\n At ${line}:${col} of ${url}`);
  };

  function readData() {
    badFunc(); // 미정의 함수
               // - 에러 발생 장소
  }

  readData();
</script>
```

##### `window.onerror` <sub>(전역 핸들러)</sub>
- 중단된 스크립트 복구 목적
  - 드물게 사용
- `window.onerror` 만으로 스크립트 복구
  - 사실상 불가능
- 개발자에게 에러 메시지 보내는 용도
- 에러 로깅 관련 상용 서비스
  - https://errorception.com
  - http://www.muscula.com
  - 기타 등등

#### 상용 서비스 동작 프로세스

##### 1. 서비스 가입 시
- JS 파일 · 스크립트 url 받음
- 페이지에 파일· url 삽입

##### 2. 받은 파일
- `window.onerror` <sub>(커스텀 함수)</sub> 설정

##### 3. 에러 발생 시
- 커스텀 함수
  - 에러 내용 담아 서비스에 네트워크 요청 보냄

##### 4. 서비스 사이트 로그인
- 기록된 에러 확인
